<?xml version="1.0" ?>
<robot name="mimic_v1_single_leg">
  <link name="base_link">
    <visual>
      <origin xyz="0 0 0" rpy="0 0 0"/>
      <geometry>
        <mesh filename="../meshes/base_link.stl" scale="0.001 0.001 0.001"/>
      </geometry>
    </visual>
    <collision>
      <origin xyz="0 0 0" rpy="0 0 0"/>
      <geometry>
        <mesh filename="../meshes/base_link.stl" scale="0.001 0.001 0.001"/>
      </geometry>
    </collision>
    <inertial>
      <origin xyz="0.000919 0.000893 -0.000839" rpy="0 0 0"/>
      <mass value="4.277848"/>
      <inertia ixx="0.03065" ixy="0.0009113" ixz="0.00157" iyy="0.01819" iyz="5.5322119e-05" izz="0.03977"/>
    </inertial>
  </link>
  <link name="upper_link_R">
    <visual>
      <origin xyz="0 0 0" rpy="0 0 0"/>
      <geometry>
        <mesh filename="../meshes/upper_link_R.stl" scale="0.001 0.001 0.001"/>
      </geometry>
    </visual>
    <collision>
      <origin xyz="0 0 0" rpy="0 0 0"/>
      <geometry>
        <mesh filename="../meshes/upper_link_R.stl" scale="0.001 0.001 0.001"/>
      </geometry>
    </collision>
    <inertial>
      <origin xyz="0.0 -0.001797 -0.087228" rpy="0 0 0"/>
      <mass value="0.072264"/>
      <inertia ixx="0.0002834" ixy="-1.205e-17" ixz="1.15e-16" iyy="0.0002835" iyz="1.3568424999999999e-05" izz="8.566684e-06"/>
    </inertial>
  </link>
  <joint name="upper_link_R_joint" type="continuous">
    <parent link="base_link"/>
    <child link="upper_link_R"/>
    <origin xyz="0.0 -0.1325 0.0" rpy="0 0 0"/>
    <axis xyz="0 1 0"/>
  </joint>
  <link name="lower_link_R">
    <visual>
      <origin xyz="0 0 0" rpy="0 0 0"/>
      <geometry>
        <mesh filename="../meshes/lower_link_R.stl" scale="0.001 0.001 0.001"/>
      </geometry>
    </visual>
    <collision>
      <origin xyz="0 0 0" rpy="0 0 0"/>
      <geometry>
        <mesh filename="../meshes/lower_link_R.stl" scale="0.001 0.001 0.001"/>
      </geometry>
    </collision>
    <inertial>
      <origin xyz="-0.000324 -0.01728 -0.135606" rpy="0 0 0"/>
      <mass value="0.696827"/>
      <inertia ixx="0.002193" ixy="1.2322395e-05" ixz="1.7489423e-05" iyy="0.001908" iyz="-0.0002534" izz="0.000758"/>
    </inertial>
  </link>
  <joint name="lower_link_R_joint" type="continuous">
    <parent link="upper_link_R"/>
    <child link="lower_link_R"/>
    <origin xyz="0.0 0.003 -0.15" rpy="0 0 0"/>
    <axis xyz="0 1 0"/>
  </joint>
  <link name="wheel_R">
    <visual>
      <origin xyz="0 0 0" rpy="0 0 0"/>
      <geometry>
        <mesh filename="../meshes/wheel_R.stl" scale="0.001 0.001 0.001"/>
      </geometry>
    </visual>
    <collision>
      <origin xyz="0 0 0" rpy="0 0 0"/>
      <geometry>
        <mesh filename="../meshes/wheel_R.stl" scale="0.001 0.001 0.001"/>
      </geometry>
    </collision>
    <inertial>
      <origin xyz="-0.000306 0.020079999999999997 -5e-06" rpy="0 0 0"/>
      <mass value="0.643498"/>
      <inertia ixx="0.001232" ixy="5.4039e-08" ixz="3.2153539999999997e-06" iyy="0.00212" iyz="1.0849999999999999e-09" izz="0.001234"/>
    </inertial>
  </link>
  <joint name="wheel_R_joint" type="continuous">
    <parent link="lower_link_R"/>
    <child link="wheel_R"/>
    <origin xyz="0.0 -0.0545 -0.15" rpy="0 0 0"/>
    <axis xyz="0 1 0"/>
  </joint>
</robot>